import * as assert from 'assert';
import { Err, ErrorHandler, InitProtector, Ok, Result, err, ok, panic, tryOrDefault } from 'src/base/common/error';
import { AreEqual, checkTrue, isString } from 'src/base/common/utilities/type';
import { shouldThrow } from 'test/utils/helpers';

suite('error-test', () => {
    
    test('setUnexpectedErrorExternalCallback', () => {
        let hit = false;
        
        ErrorHandler.setUnexpectedErrorExternalCallback(err => { hit = true; });
        ErrorHandler.onUnexpectedError(undefined);

        assert.strictEqual(hit, true);
    });

    test('registerListener', () => {
        let hit = 0;
        
        ErrorHandler.setUnexpectedErrorExternalCallback(() => {});

        const listener1 = ErrorHandler.registerListener(() => hit++);
        const listener2 = ErrorHandler.registerListener(() => hit++);

        ErrorHandler.onUnexpectedError(undefined);
        listener1.dispose();
        ErrorHandler.onUnexpectedError(undefined);
        listener2.dispose();
        ErrorHandler.onUnexpectedError(undefined);

        assert.strictEqual(hit, 3);
    });

    test('onUnexpectedExternalError', () => {
        let hit = 0;
        
        ErrorHandler.setUnexpectedErrorExternalCallback(() => hit--);

        const listener = ErrorHandler.registerListener(() => hit++);
        ErrorHandler.onUnexpectedExternalError(undefined);
        
        assert.strictEqual(hit, -1);
    });

    test('tryOrDefault', () => {
        assert.strictEqual(tryOrDefault('bad world', () => 'hello world'), 'hello world');
        assert.strictEqual(tryOrDefault('bad world', () => { throw new Error(); }), 'bad world');
    });

    test('InitProtector', () => {
        const initProtector = new InitProtector();

        initProtector.init('first init');
        shouldThrow(() => initProtector.init('second init'));
        shouldThrow(() => initProtector.init('thrid init'));
    });
});

suite('result-test', () => {

    suite('Ok', () => {
        const okInstance: Result<number, string> = new Ok(42);

        test('isOk method should return true', () => {
            assert.ok(okInstance.isOk());
        });

        test('isErr method should return false', () => {
            assert.ok(!okInstance.isErr());
        });

        test('unwrap should return inner data', () => {
            assert.strictEqual(okInstance.unwrap(), 42);
        });

        test('unwrapOr should return inner data regardless of provided data', () => {
            assert.strictEqual(okInstance.unwrapOr(0), 42);
        });

        test('expect should return inner data regardless of error message', () => {
            assert.strictEqual(okInstance.expect('This should not be thrown'), 42);
        });

        test('match should apply onOk function and return its result', () => {
            assert.strictEqual(okInstance.match(data => data + 1, _ => 0), 43);
        });
    });

    suite('Err', () => {
        const errInstance: Result<number, string> = new Err("Error Message");

        test('isOk method should return false', () => {
            assert.ok(!errInstance.isOk());
        });

        test('isErr method should return true', () => {
            assert.ok(errInstance.isErr());
        });

        test('unwrap should throw an error', () => {
            assert.throws(() => {
                errInstance.unwrap();
            });
        });

        test('unwrapOr should return provided default value', () => {
            assert.strictEqual(errInstance.unwrapOr(0), 0);
        });

        test('expect should throw provided error message', () => {
            assert.throws(() => {
                errInstance.expect('Custom Error Message');
            }, {
                message: 'Custom Error Message'
            });
        });

        test('match should apply onError function and return its result', () => {
            assert.strictEqual(errInstance.match(num => 'onSuccess', err => 'onError'), 'onError');
        });
    });

    suite('Result', () => {

        function getResult(value: boolean): Result<string, Error> {
            if (value) {
                return ok('ok');
            }
            return err(new Error('err'));
        }

        test('isOk type-check', () => {
            const result = getResult(true);
            if (result.isOk()) {
                checkTrue<AreEqual<typeof result.data, string>>();
            } else {
                checkTrue<AreEqual<typeof result.data, Error>>();
            }
        });

        test('isErr type-check', () => {
            const result = getResult(true);
            if (result.isErr()) {
                checkTrue<AreEqual<typeof result.data, Error>>();
            } else {
                checkTrue<AreEqual<typeof result.data, string>>();
            }
        });
        
        test('unwrap type-check', () => {
            const result = getResult(true);
            const str = result.unwrap();
            checkTrue<AreEqual<typeof str, string>>();
        });
        
        test('unwrapOr type-check', () => {
            const result = getResult(true);
            const str = result.unwrapOr('default');
            checkTrue<AreEqual<typeof str, string>>();
        });
        
        test('expect type-check', () => {
            const result = getResult(true);
            const str = result.expect('expect error message');
            checkTrue<AreEqual<typeof str, string>>();
        });
        
        test('match type-check', () => {
            const result = getResult(true);
            result.match(
                (data) => {
                    assert.ok(isString(data));
                    checkTrue<AreEqual<typeof data, string>>();
                }, 
                (err) => {
                    assert.ok(err instanceof Error);
                    checkTrue<AreEqual<typeof err, Error>>();
                },
            );
        });
    });

    suite('panic', () => {
        test('should throw provided error message', () => {
            assert.throws(() => {
                panic('Panic Error Message');
            }, {
                message: 'Panic Error Message'
            });
        });
    });

    suite('Result-namespace', () => {

        test('fromThrowable', () => {
            
            function mightFail(): number {
                throw new Error("Failed!");
            }

            function notFail(): number {
                return 42;
            }

            // not failed
            const result1 = Result.fromThrowable<number, string>(
                notFail, 
                (error: any) => {
                    return error.message;
                }
            );
            assert.strictEqual(result1.data, 42);

            // failed
            const result2 = Result.fromThrowable<number, string>(
                mightFail, 
                (error: any) => {
                    return error.message;
                }
            );
            assert.strictEqual(result2.data, 'Failed!');
        });
    });
});